❯ python -m unittest Tests/test_PostgresDB.py > error.log
2024-02-17 18:55:36.917 | INFO     | LoguruModule.code:wrapper:19 - Вызов функции load_dataframe с аргументами: args = (<PostgresDBModule.code.PostgresDBClass object at 0x7f418bb7bd50>,    col1
0     1
1     2
2     3, 'SESSION'), kwargs = {}
2024-02-17 18:55:36.962 | INFO     | LoguruModule.code:wrapper:21 - Результат выполнения функции load_dataframe: result = None
F
======================================================================
FAIL: test_load_dataframe (Tests.test_PostgresDB.TestPostgresDBClass.test_load_dataframe)
----------------------------------------------------------------------
Traceback (most recent call last):
  File "/home/viktorlov/PycharmProjects/_cloned/ETHUSDT_BTCUSDT/Tests/test_PostgresDB.py", line 40, in test_load_dataframe
    mock_read_sql.assert_called_once_with('SESSION', mock_engine_instance, columns=['datetime'])
  File "/usr/lib/python3.11/unittest/mock.py", line 951, in assert_called_once_with
    return self.assert_called_with(*args, **kwargs)
           ^^^^^^^^^^^^^^^^^^^^^^^^^^^^^^^^^^^^^^^^
  File "/usr/lib/python3.11/unittest/mock.py", line 939, in assert_called_with
    raise AssertionError(_error_message()) from cause
AssertionError: expected call not found.
Expected: read_sql('SESSION', <MagicMock name='create_engine()' id='139919487541008'>, columns=['datetime'])
  Actual: read_sql('SESSION', Engine(postgresql://postgres:***@localhost:5432/diploma), columns=['datetime'])

----------------------------------------------------------------------
Ran 1 test in 0.176s

FAILED (failures=1)
